# Exception Handling
#
# finally block

try:
    print(x)
except:
    print("Something went wrong", end='\n')
finally:
    print("The 'try except' is finished", end="\n")
